<?xml version="1.0" encoding="utf-8"?>
<!-- This URDF was automatically created by SolidWorks to URDF Exporter! Originally created by Stephen Brawner (brawner@gmail.com) 
     Commit Version: 1.6.0-4-g7f85cfe  Build Version: 1.6.7995.38578
     For more information, please see http://wiki.ros.org/sw_urdf_exporter -->
<robot
  name="Namtransformer">
  <link
    name="Baselink">
    <inertial>
      <origin
        xyz="0.0178281773423112 -0.000596193577132142 0.0390696544458441"
        rpy="0 0 0" />
      <mass
        value="1.22532136336732" />
      <inertia
        ixx="0.00229793837165269"
        ixy="-1.09227305641069E-06"
        ixz="-4.7535582473934E-06"
        iyy="0.00366893850816306"
        iyz="-1.24073959536616E-05"
        izz="0.00557967347318409" />
    </inertial>
    <visual>
      <origin
        xyz="0 0 0"
        rpy="0 0 0" />
      <geometry>
        <mesh
          filename="/home/nam/Transform_Bipedal/Namtransformer/meshes/Baselink.STL" />
      </geometry>
      <material
        name="">
        <color
          rgba="0.792156862745098 0.819607843137255 0.933333333333333 1" />
      </material>
    </visual>
    <collision>
      <origin
        xyz="0 0 0"
        rpy="0 0 0" />
      <geometry>
        <mesh
          filename="/home/nam/Transform_Bipedal/Namtransformer/meshes/Baselink.STL" />
      </geometry>
    </collision>
  </link>
  <link
    name="Bubleft">
    <inertial>
      <origin
        xyz="0.00077222252897205 1.48980082437244E-08 0.0144402391383288"
        rpy="0 0 0" />
      <mass
        value="0.0541320948471736" />
      <inertia
        ixx="1.9153591360639E-05"
        ixy="1.05076891258394E-11"
        ixz="-1.29770853899577E-06"
        iyy="4.63922160357352E-05"
        iyz="-1.26060804500177E-11"
        izz="4.32236807688339E-05" />
    </inertial>
    <visual>
      <origin
        xyz="0 0 0"
        rpy="0 0 0" />
      <geometry>
        <mesh
          filename="/home/nam/Transform_Bipedal/Namtransformer/meshes/Bubleft.STL" />
      </geometry>
      <material
        name="">
        <color
          rgba="0.792156862745098 0.819607843137255 0.933333333333333 1" />
      </material>
    </visual>
    <collision>
      <origin
        xyz="0 0 0"
        rpy="0 0 0" />
      <geometry>
        <mesh
          filename="/home/nam/Transform_Bipedal/Namtransformer/meshes/Bubleft.STL" />
      </geometry>
    </collision>
  </link>
  <joint
    name="Bubleft_joint"
    type="revolute">
    <origin
      xyz="0.04025 -0.07995 0.0229"
      rpy="1.5708 0 -1.5708" />
    <parent
      link="Baselink" />
    <child
      link="Bubleft" />
    <axis
      xyz="0 0 1" />
    <limit
      lower="-0.1243"
      upper="3.1382"
      effort="10.3"
      velocity="3.67" />
  </joint>
  <link
    name="Hipleft">
    <inertial>
      <origin
        xyz="-0.000270077964393295 -0.0684560755966682 -0.0028627074599214"
        rpy="0 0 0" />
      <mass
        value="0.318234889909563" />
      <inertia
        ixx="0.000267811380487872"
        ixy="3.1189883914483E-06"
        ixz="-4.88860066637297E-07"
        iyy="0.000174268008727696"
        iyz="1.00382672886602E-05"
        izz="0.000178026829294934" />
    </inertial>
    <visual>
      <origin
        xyz="0 0 0"
        rpy="0 0 0" />
      <geometry>
        <mesh
          filename="/home/nam/Transform_Bipedal/Namtransformer/meshes/Hipleft.STL" />
      </geometry>
      <material
        name="">
        <color
          rgba="0.792156862745098 0.819607843137255 0.933333333333333 1" />
      </material>
    </visual>
    <collision>
      <origin
        xyz="0 0 0"
        rpy="0 0 0" />
      <geometry>
        <mesh
          filename="/home/nam/Transform_Bipedal/Namtransformer/meshes/Hipleft.STL" />
      </geometry>
    </collision>
  </link>
  <joint
    name="Hipleft_joint"
    type="revolute">
    <origin
      xyz="-0.0003 0 0.03995"
      rpy="0 1.5708 0" />
    <parent
      link="Bubleft" />
    <child
      link="Hipleft" />
    <axis
      xyz="0 0 1" />
    <limit
      lower="-0.6351"
      upper="0.3710"
      effort="10.3"
      velocity="3.67" />
  </joint>
  <link
    name="Kneeleft">
    <inertial>
      <origin
        xyz="-9.10743707689121E-05 -0.0833827270009606 -0.000267332755809941"
        rpy="0 0 0" />
      <mass
        value="0.347003571766794" />
      <inertia
        ixx="0.000557550118349417"
        ixy="1.15563519429093E-12"
        ixz="2.8378606840889E-12"
        iyy="0.000189361803411248"
        iyz="-5.9723142023858E-08"
        izz="0.000461856679037699" />
    </inertial>
    <visual>
      <origin
        xyz="0 0 0"
        rpy="0 0 0" />
      <geometry>
        <mesh
          filename="/home/nam/Transform_Bipedal/Namtransformer/meshes/Kneeleft.STL" />
      </geometry>
      <material
        name="">
        <color
          rgba="0.792156862745098 0.819607843137255 0.933333333333333 1" />
      </material>
    </visual>
    <collision>
      <origin
        xyz="0 0 0"
        rpy="0 0 0" />
      <geometry>
        <mesh
          filename="/home/nam/Transform_Bipedal/Namtransformer/meshes/Kneeleft.STL" />
      </geometry>
    </collision>
  </link>
  <joint
    name="Kneeleft_joint"
    type="revolute">
    <origin
      xyz="0.0001 -0.1851 -0.0042"
      rpy="0 0 0" />
    <parent
      link="Hipleft" />
    <child
      link="Kneeleft" />
    <axis
      xyz="0 0 1" />
    <limit
      lower="-1.5127"
      upper="1.4831"
      effort="10.3"
      velocity="3.67" />
  </joint>
  <link
    name="Footleft">
    <inertial>
      <origin
        xyz="0.0366739745450469 -0.0173790625821897 -0.000787772819295329"
        rpy="0 0 0" />
      <mass
        value="0.213822721783652" />
      <inertia
        ixx="0.000122852396459888"
        ixy="-6.57031337184045E-05"
        ixz="7.51392532358998E-08"
        iyy="0.000270815079907506"
        iyz="4.99182479230873E-09"
        izz="0.000254522195692041" />
    </inertial>
    <visual>
      <origin
        xyz="0 0 0"
        rpy="0 0 0" />
      <geometry>
        <mesh
          filename="/home/nam/Transform_Bipedal/Namtransformer/meshes/Footleft.STL" />
      </geometry>
      <material
        name="">
        <color
          rgba="0.792156862745098 0.819607843137255 0.933333333333333 1" />
      </material>
    </visual>
    <collision>
      <origin
        xyz="0 0 0"
        rpy="0 0 0" />
      <geometry>
        <mesh
          filename="/home/nam/Transform_Bipedal/Namtransformer/meshes/Footleft.STL" />
      </geometry>
    </collision>
  </link>
  <joint
    name="Footleft_joint"
    type="revolute">
    <origin
      xyz="-0.0003 -0.19 0.00095"
      rpy="0 0 0" />
    <parent
      link="Kneeleft" />
    <child
      link="Footleft" />
    <axis
      xyz="0 0 1" />
    <limit
      lower="-1.1381"
      upper="0.7027"
      effort="2.94"
      velocity="4.82" />
  </joint>
  <link
    name="Foeleft">
    <inertial>
      <origin
        xyz="-0.00958767324655235 -4.29517532651857E-15 4.99999999999945E-05"
        rpy="0 0 0" />
      <mass
        value="0.000134156637061464" />
      <inertia
        ixx="8.50314418786422E-08"
        ixy="-1.63414262960503E-20"
        ixz="-2.19865261641575E-23"
        iyy="1.65141883893155E-07"
        iyz="-7.87874939257139E-23"
        izz="2.50173102177402E-07" />
    </inertial>
    <visual>
      <origin
        xyz="0 0 0"
        rpy="0 0 0" />
      <geometry>
        <mesh
          filename="/home/nam/Transform_Bipedal/Namtransformer/meshes/Foeleft.STL" />
      </geometry>
      <material
        name="">
        <color
          rgba="0.792156862745098 0.819607843137255 0.933333333333333 1" />
      </material>
    </visual>
    <collision>
      <origin
        xyz="0 0 0"
        rpy="0 0 0" />
      <geometry>
        <mesh
          filename="/home/nam/Transform_Bipedal/Namtransformer/meshes/Foeleft.STL" />
      </geometry>
    </collision>
  </link>
  <joint
    name="Foeleft_joint"
    type="fixed">
    <origin
      xyz="0.01 -0.0451 0"
      rpy="-1.5708 0 0" />
    <parent
      link="Footleft" />
    <child
      link="Foeleft" />
    <axis
      xyz="0 0 0" />
  </joint>
  <link
    name="Bubright">
    <inertial>
      <origin
        xyz="-0.000772222528972077 -1.48980082159689E-08 0.0144402391383288"
        rpy="0 0 0" />
      <mass
        value="0.0541320948471737" />
      <inertia
        ixx="1.9153591360639E-05"
        ixy="1.0507689117609E-11"
        ixz="1.2977085389958E-06"
        iyy="4.63922160357353E-05"
        iyz="1.26060804552407E-11"
        izz="4.3223680768834E-05" />
    </inertial>
    <visual>
      <origin
        xyz="0 0 0"
        rpy="0 0 0" />
      <geometry>
        <mesh
          filename="/home/nam/Transform_Bipedal/Namtransformer/meshes/Bubright.STL" />
      </geometry>
      <material
        name="">
        <color
          rgba="0.792156862745098 0.819607843137255 0.933333333333333 1" />
      </material>
    </visual>
    <collision>
      <origin
        xyz="0 0 0"
        rpy="0 0 0" />
      <geometry>
        <mesh
          filename="/home/nam/Transform_Bipedal/Namtransformer/meshes/Bubright.STL" />
      </geometry>
    </collision>
  </link>
  <joint
    name="Bubright_joint"
    type="revolute">
    <origin
      xyz="0.04025 0.07995 0.0229"
      rpy="1.5708 0 -1.5708" />
    <parent
      link="Baselink" />
    <child
      link="Bubright" />
    <axis
      xyz="0 0 -1" />
    <limit
      lower="-0.1243"
      upper="3.1382"
      effort="10.3"
      velocity="3.67" />
  </joint>
  <link
    name="Hipright">
    <inertial>
      <origin
        xyz="-0.000270081557997293 -0.0684560993055165 0.00286268892115618"
        rpy="0 0 0" />
      <mass
        value="0.318234408091769" />
      <inertia
        ixx="0.000267811204266692"
        ixy="3.11914095953242E-06"
        ixz="4.88817409078737E-07"
        iyy="0.000174267837279053"
        iyz="-1.00379998284171E-05"
        izz="0.00017802683796978" />
    </inertial>
    <visual>
      <origin
        xyz="0 0 0"
        rpy="0 0 0" />
      <geometry>
        <mesh
          filename="/home/nam/Transform_Bipedal/Namtransformer/meshes/Hipright.STL" />
      </geometry>
      <material
        name="">
        <color
          rgba="0.792156862745098 0.819607843137255 0.933333333333333 1" />
      </material>
    </visual>
    <collision>
      <origin
        xyz="0 0 0"
        rpy="0 0 0" />
      <geometry>
        <mesh
          filename="/home/nam/Transform_Bipedal/Namtransformer/meshes/Hipright.STL" />
      </geometry>
    </collision>
  </link>
  <joint
    name="Hipright_joint"
    type="revolute">
    <origin
      xyz="0.0003 0 0.03995"
      rpy="0 1.5708 0" />
    <parent
      link="Bubright" />
    <child
      link="Hipright" />
    <axis
      xyz="0 0 1" />
    <limit
      lower="-0.6351"
      upper="0.3710"
      effort="10.3"
      velocity="3.67" />
  </joint>
  <link
    name="Kneeright">
    <inertial>
      <origin
        xyz="9.10743707689676E-05 -0.0833827270009605 0.000619515103848028"
        rpy="0 0 0" />
      <mass
        value="0.347003571766794" />
      <inertia
        ixx="0.000557550118349417"
        ixy="-1.155635199707E-12"
        ixz="2.83786078036127E-12"
        iyy="0.000189361803411248"
        iyz="5.97231420239128E-08"
        izz="0.000461856679037699" />
    </inertial>
    <visual>
      <origin
        xyz="0 0 0"
        rpy="0 0 0" />
      <geometry>
        <mesh
          filename="/home/nam/Transform_Bipedal/Namtransformer/meshes/Kneeright.STL" />
      </geometry>
      <material
        name="">
        <color
          rgba="0.792156862745098 0.819607843137255 0.933333333333333 1" />
      </material>
    </visual>
    <collision>
      <origin
        xyz="0 0 0"
        rpy="0 0 0" />
      <geometry>
        <mesh
          filename="/home/nam/Transform_Bipedal/Namtransformer/meshes/Kneeright.STL" />
      </geometry>
    </collision>
  </link>
  <joint
    name="Kneeright_joint"
    type="revolute">
    <origin
      xyz="0.0001 -0.1851 0.0042"
      rpy="0 0 0" />
    <parent
      link="Hipright" />
    <child
      link="Kneeright" />
    <axis
      xyz="0 0 1" />
    <limit
      lower="-1.5127"
      upper="1.4831"
      effort="10.3"
      velocity="3.67" />
  </joint>
  <link
    name="Footright">
    <inertial>
      <origin
        xyz="0.0366739745372401 -0.0172788988036042 0.000213862435749071"
        rpy="0 0 0" />
      <mass
        value="0.213822720063559" />
      <inertia
        ixx="0.00012285239596614"
        ixy="-6.57031338815185E-05"
        ixz="7.51396648870402E-08"
        iyy="0.00027081507908138"
        iyz="4.99152340249119E-09"
        izz="0.000254522195218109" />
    </inertial>
    <visual>
      <origin
        xyz="0 0 0"
        rpy="0 0 0" />
      <geometry>
        <mesh
          filename="/home/nam/Transform_Bipedal/Namtransformer/meshes/Footright.STL" />
      </geometry>
      <material
        name="">
        <color
          rgba="0.792156862745098 0.819607843137255 0.933333333333333 1" />
      </material>
    </visual>
    <collision>
      <origin
        xyz="0 0 0"
        rpy="0 0 0" />
      <geometry>
        <mesh
          filename="/home/nam/Transform_Bipedal/Namtransformer/meshes/Footright.STL" />
      </geometry>
    </collision>
  </link>
  <joint
    name="Footright_joint"
    type="revolute">
    <origin
      xyz="0.0003 -0.19 -0.00045"
      rpy="0 0 0" />
    <parent
      link="Kneeright" />
    <child
      link="Footright" />
    <axis
      xyz="0 0 1" />
    <limit
      lower="-1.1381"
      upper="0.7027"
      effort="2.94"
      velocity="4.82" />
  </joint>
  <link
    name="Foeright">
    <inertial>
      <origin
        xyz="-0.0095876732465453 -2.41473507855972E-15 4.9999999999939E-05"
        rpy="0 0 0" />
      <mass
        value="0.000134156637061435" />
      <inertia
        ixx="8.50314418786368E-08"
        ixy="-6.60960382915247E-21"
        ixz="2.32992284588935E-23"
        iyy="1.65141883893133E-07"
        iyz="-2.74243431028626E-24"
        izz="2.50173102177375E-07" />
    </inertial>
    <visual>
      <origin
        xyz="0 0 0"
        rpy="0 0 0" />
      <geometry>
        <mesh
          filename="/home/nam/Transform_Bipedal/Namtransformer/meshes/Foeright.STL" />
      </geometry>
      <material
        name="">
        <color
          rgba="0.792156862745098 0.819607843137255 0.933333333333333 1" />
      </material>
    </visual>
    <collision>
      <origin
        xyz="0 0 0"
        rpy="0 0 0" />
      <geometry>
        <mesh
          filename="/home/nam/Transform_Bipedal/Namtransformer/meshes/Foeright.STL" />
      </geometry>
    </collision>
  </link>
  <joint
    name="Foeright_joint"
    type="fixed">
    <origin
      xyz="0.01 -0.0451 0"
      rpy="-1.5708 0 0" />
    <parent
      link="Footright" />
    <child
      link="Foeright" />
    <axis
      xyz="0 0 0" />
  </joint>
</robot>
